Workbook

Sheet LEDGER
A3: Cost Code | B3: Date | C3: Invoice # | D3: Payee | E3: Description | F3: Amount | G3: Amount Paid | H3: Amount Due | I3: Funding Source
A4: 0.0001 | D4: Disbursement #00 | F4: 593250 | G4: 593250 | H4: =F4-G4 | I4: VENTANAS I
A5: 0.0002 | D5: Disbursement #00 | F5: 7507599.7 | G5: 7507599.7 | H5: =F5-G5 | I5: VENTANAS I
A6: 0.0002 | D6: Disbursement #00 | F6: 1875000 | G6: 1875000 | H6: =F6-G6 | I6: VENTANAS I
A7: 0.3.1 | D7: Disbursement #00 | F7: 7950 | G7: 0 | H7: =F7-G7
A8: 0.4 | D8: Disbursement #00 | F8: 11250 | G8: 0 | H8: =F8-G8
A9: 0.6.2 | D9: Disbursement #00 | F9: 4800 | G9: 0 | H9: =F9-G9
A10: 0.6.3 | D10: Disbursement #00 | F10: 2400 | G10: 0 | H10: =F10-G10
A11: 0.7 | D11: Disbursement #00 | F11: 42375 | G11: 0 | H11: =F11-G11
A12: 0.8 | D12: Disbursement #00 | F12: 20000 | G12: 0 | H12: =F12-G12
A13: 0.9 | D13: Disbursement #00 | F13: 6000 | G13: 0 | H13: =F13-G13
A14: 0.9 | D14: Disbursement #00 | F14: 6480 | G14: 0 | H14: =F14-G14
A15: 2.1.1 | D15: Disbursement #00 | F15: 14500 | G15: 0 | H15: =F15-G15
A16: 3.1 | D16: Disbursement #00 | F16: 8236.005 | G16: 0 | H16: =F16-G16
A17: 3.3 | D17: Disbursement #00 | F17: 3779.624 | G17: 0 | H17: =F17-G17
A18: 3.4 | D18: Disbursement #00 | F18: 7342.175 | G18: 0 | H18: =F18-G18
... A25: 0.1 | D25: Disbursement #00 | F25: 450000 | G25: 450000 | H25: =F25-G25
A26: 3.2 | D26: Disbursement #01 - 06/05/2024 | E26: Topography Lidar | F26: 25000 | G26: 25000 | H26: =F26-G26
A27: 3.2 | D27: Disbursement #01 - 06/05/2024 | E27: Topography vat tax Pending | F27: 3250 | G27: 3250 | H27: =F27-G27
A28: 0.0001 | D28: Disbursement #01 - 06/05/2024 | E28: Soil analysis | F28: 10170 | G28: 10170 | H28: =F28-G28
A29: 0.0001 | D29: Disbursement #01 - 06/05/2024 | E29: Boundary Analysis and Marking | F29: 5085 | G29: 5085 | H29: =F29-G29
A30: 0.0001 | D30: Disbursement #01 - 06/05/2024 | E30: Water testing | F30: 1915.35 | G30: 1915.35 | H30: =F30-G30
A31: 0.0001 | D31: Disbursement #01 - 06/05/2024 | E31: Environmental Feasibility Report | F31: 8737.16 | G31: 8737.16 | H31: =F31-G31
A32: 0.0001 | D32: Disbursement #01 - 06/05/2024 | E32: Tree Trimming $880+Vat per day | F32: 4972 | G32: 4972 | H32: =F32-G32
A33: 0.3.1 | D33: Disbursement #01 - 06/05/2024 | E33: Constitution of 13 Corps | F33: 0 | G33: 0 | H33: =F33-G33
A34: 0.3.1 | D34: Disbursement #01 - 06/05/2024 | E34: 13 Certifications for Muni Application | F34: 983.1 | G34: 983.1 | H34: =F34-G34
A35: 0.3.1 | D35: Disbursement #01 - 06/05/2024 | E35: Constitution of 2 Corps | F35: 2034 | G35: 2034 | H35: =F35-G35
A36: 0.2 | D36: Disbursement #01 - 06/05/2024 | E36: 2 Certifications for Muni Application | F36: 151.25 | G36: 151.25 | H36: =F36-G36
A37: 0.0001 | D37: Disbursement #01 - 06/05/2024 | E37: Legal Fees (local Attorney plus Municipal and Environmental fees) | F37: 25000 | G37: 25000 | H37: =F37-G37
... A126: 6.3 | D126: Disbursement #09 - 04/10/2025 | E126: Work with topographer | F126: 141.25 | G126: 141.25 | H126: =F126-G126
A127: 0.7 | D127: Disbursement #10 - 05/01/2025 | E127: Development Director Abril 2025 | F127: 14125 | G127: 14125 | H127: =F127-G127 | I127: 14125
A128: 0.4 | D128: Disbursement #10 - 05/01/2025 | E128: Admin Fee Budget + Financial Controller 25% Salary Abril 2025 | F128: 3750 | G128: 3750 | H128: =F128-G128 | I128: 6150
A129: 0.6.1 | D129: Disbursement #10 - 05/01/2025 | E129: Farm Manager + Worker April 2025 | F129: 1600 | G129: 1600 | H129: =F129-G129 | I129: 6150
A130: 0.6.1 | D130: Disbursement #10 - 05/01/2025 | E130: CCSS (Social Security) April 2025 | F130: 800 | G130: 800 | H130: =F130-G130 | I130: 6150
A131: 6.3 | D131: Disbursement #10 - 05/01/2025 | E131: Internal Road (Cinco Ventanas) Materials | F131: 4000 | G131: 4000 | H131: =F131-G131
A132: 0.5 | D132: Disbursement #10 - 05/01/2025 | E132: Owners expenses pay back to CWL | F132: 14851.54 | G132: 14851.54 | H132: =F132-G132
A133: 0.911 | D133: Disbursement #10 - 05/01/2025 | E133: Construction Works in Piñuela – Gates | F133: 1400 | G133: 1400 | H133: =F133-G133
A134: 3.1 | D134: Disbursement #10 - 05/01/2025 | E134: Forest stratification technical analysis. | F134: 3390 | G134: 3390 | H134: =F134-G134
A135: 0.7 | D135: Disbursement #11 - 06/01/2025 | E135: Development Director MAY 2025 | F135: 14125 | G135: 14125 | H135: =F135-G135 | I135: 14125
A136: 0.4 | D136: Disbursement #11 - 06/01/2025 | E136: Admin Fee Budget + Financial Controller 25% Salary MAY 2025 | F136: 3750 | G136: 3750 | H136: =F136-G136 | I136: 6150
...

Sheet Timeline Detail
A3: Project Category | B3: Phase | C3: WBS NUMBER | D3: Task Title | E3: Budget Revised | F3: YTD Expense | G3: Remaining | H3: Forecast
A4: =IFERROR(INDEX('Job Cost Report'!$E:$E,MATCH($C4,'Job Cost Report'!$B:$B,0)),"") | B4: =IFERROR(INDEX('Job Cost Report'!$F:$F,MATCH($C4,'Job Cost Report'!$B:$B,0)),"") | C4: 0.0001 | D4: =IFERROR(INDEX('Job Cost Report'!$C:$C,MATCH($C4,'Job Cost Report'!$B:$B,0)),"") | E4: =SUMIF('Job Cost Report'!$B:$B,$C4,'Job Cost Report'!$I:$I) | F4: =SUMIF('Job Cost Report'!$B:$B,$C4,'Job Cost Report'!$J:$J) | G4: =SUMIF('Job Cost Report'!$B:$B,$C4,'Job Cost Report'!$K:$K) | H4: =SUMIF('Job Cost Report'!$B:$B,$C4,'Job Cost Report'!$L:$L)
A5: =IFERROR(INDEX('Job Cost Report'!$E:$E,MATCH($C5,'Job Cost Report'!$B:$B,0)),"") | B5: =IFERROR(INDEX('Job Cost Report'!$F:$F,MATCH($C5,'Job Cost Report'!$B:$B,0)),"") | C5: 0.0002 | D5: =IFERROR(INDEX('Job Cost Report'!$C:$C,MATCH($C5,'Job Cost Report'!$B:$B,0)),"") | E5: =SUMIF('Job Cost Report'!$B:$B,$C5,'Job Cost Report'!$I:$I) | F5: =SUMIF('Job Cost Report'!$B:$B,$C5,'Job Cost Report'!$J:$J) | G5: =SUMIF('Job Cost Report'!$B:$B,$C5,'Job Cost Report'!$K:$K) | H5: =SUMIF('Job Cost Report'!$B:$B,$C5,'Job Cost Report'!$L:$L)
A6: =IFERROR(INDEX('Job Cost Report'!$E:$E,MATCH($C6,'Job Cost Report'!$B:$B,0)),"") | B6: =IFERROR(INDEX('Job Cost Report'!$F:$F,MATCH($C6,'Job Cost Report'!$B:$B,0)),"") | C6: 2.1.1 | D6: =IFERROR(INDEX('Job Cost Report'!$C:$C,MATCH($C6,'Job Cost Report'!$B:$B,0)),"") | E6: =SUMIF('Job Cost Report'!$B:$B,$C6,'Job Cost Report'!$I:$I) | F6: =SUMIF('Job Cost Report'!$B:$B,$C6,'Job Cost Report'!$J:$J) | G6: =SUMIF('Job Cost Report'!$B:$B,$C6,'Job Cost Report'!$K:$K) | H6: =SUMIF('Job Cost Report'!$B:$B,$C6,'Job Cost Report'!$L:$L)
A7: =IFERROR(INDEX('Job Cost Report'!$E:$E,MATCH($C7,'Job Cost Report'!$B:$B,0)),"") | B7: =IFERROR(INDEX('Job Cost Report'!$F:$F,MATCH($C7,'Job Cost Report'!$B:$B,0)),"") | C7: 2.1.2 | D7: =IFERROR(INDEX('Job Cost Report'!$C:$C,MATCH($C7,'Job Cost Report'!$B:$B,0)),"") | E7: =SUMIF('Job Cost Report'!$B:$B,$C7,'Job Cost Report'!$I:$I) | F7: =SUMIF('Job Cost Report'!$B:$B,$C7,'Job Cost Report'!$J:$J) | G7: =SUMIF('Job Cost Report'!$B:$B,$C7,'Job Cost Report'!$K:$K) | H7: =SUMIF('Job Cost Report'!$B:$B,$C7,'Job Cost Report'!$L:$L)
A8: =IFERROR(INDEX('Job Cost Report'!$E:$E,MATCH($C8,'Job Cost Report'!$B:$B,0)),"") | B8: =IFERROR(INDEX('Job Cost Report'!$F:$F,MATCH($C8,'Job Cost Report'!$B:$B,0)),"") | C8: 2.1.3 | D8: =IFERROR(INDEX('Job Cost Report'!$C:$C,MATCH($C8,'Job Cost Report'!$B:$B,0)),"") | E8: =SUMIF('Job Cost Report'!$B:$B,$C8,'Job Cost Report'!$I:$I) | F8: =SUMIF('Job Cost Report'!$B:$B,$C8,'Job Cost Report'!$J:$J) | G8: =SUMIF('Job Cost Report'!$B:$B,$C8,'Job Cost Report'!$K:$K) | H8: =SUMIF('Job Cost Report'!$B:$B,$C8,'Job Cost Report'!$L:$L)
A9: =IFERROR(INDEX('Job Cost Report'!$E:$E,MATCH($C9,'Job Cost Report'!$B:$B,0)),"") | B9: =IFERROR(INDEX('Job Cost Report'!$F:$F,MATCH($C9,'Job Cost Report'!$B:$B,0)),"") | C9: 2.1.4 | D9: =IFERROR(INDEX('Job Cost Report'!$C:$C,MATCH($C9,'Job Cost Report'!$B:$B,0)),"") | E9: =SUMIF('Job Cost Report'!$B:$B,$C9,'Job Cost Report'!$I:$I) | F9: =SUMIF('Job Cost Report'!$B:$B,$C9,'Job Cost Report'!$J:$J) | G9: =SUMIF('Job Cost Report'!$B:$B,$C9,'Job Cost Report'!$K:$K) | H9: =SUMIF('Job Cost Report'!$B:$B,$C9,'Job Cost Report'!$L:$L)
A10: =IFERROR(INDEX('Job Cost Report'!$E:$E,MATCH($C10,'Job Cost Report'!$B:$B,0)),"") | B10: =IFERROR(INDEX('Job Cost Report'!$F:$F,MATCH($C10,'Job Cost Report'!$B:$B,0)),"") | C10: 2.2 | D10: =IFERROR(INDEX('Job Cost Report'!$C:$C,MATCH($C10,'Job Cost Report'!$B:$B,0)),"") | E10: =SUMIF('Job Cost Report'!$B:$B,$C10,'Job Cost Report'!$I:$I) | F10: =SUMIF('Job Cost Report'!$B:$B,$C10,'Job Cost Report'!$J:$J) | G10: =SUMIF('Job Cost Report'!$B:$B,$C10,'Job Cost Report'!$K:$K) | H10: =SUMIF('Job Cost Report'!$B:$B,$C10,'Job Cost Report'!$L:$L)
A11: =IFERROR(INDEX('Job Cost Report'!$E:$E,MATCH($C11,'Job Cost Report'!$B:$B,0)),"") | B11: =IFERROR(INDEX('Job Cost Report'!$F:$F,MATCH($C11,'Job Cost Report'!$B:$B,0)),"") | C11: 9.1.1 | D11: =IFERROR(INDEX('Job Cost Report'!$C:$C,MATCH($C11,'Job Cost Report'!$B:$B,0)),"") | E11: =SUMIF('Job Cost Report'!$B:$B,$C11,'Job Cost Report'!$I:$I) | F11: =SUMIF('Job Cost Report'!$B:$B,$C11,'Job Cost Report'!$J:$J) | G11: =SUMIF('Job Cost Report'!$B:$B,$C11,'Job Cost Report'!$K:$K) | H11: =SUMIF('Job Cost Report'!$B:$B,$C11,'Job Cost Report'!$L:$L)
A12: =IFERROR(INDEX('Job Cost Report'!$E:$E,MATCH($C12,'Job Cost Report'!$B:$B,0)),"") | B12: =IFERROR(INDEX('Job Cost Report'!$F:$F,MATCH($C12,'Job Cost Report'!$B:$B,0)),"") | C12: 9.1.2 | D12: =IFERROR(INDEX('Job Cost Report'!$C:$C,MATCH($C12,'Job Cost Report'!$B:$B,0)),"") | E12: =SUMIF('Job Cost Report'!$B:$B,$C12,'Job Cost Report'!$I:$I) | F12: =SUMIF('Job Cost Report'!$B:$B,$C12,'Job Cost Report'!$J:$J) | G12: =SUMIF('Job Cost Report'!$B:$B,$C12,'Job Cost Report'!$K:$K) | H12: =SUMIF('Job Cost Report'!$B:$B,$C12,'Job Cost Report'!$L:$L)
A13: =IFERROR(INDEX('Job Cost Report'!$E:$E,MATCH($C13,'Job Cost Report'!$B:$B,0)),"") | B13: =IFERROR(INDEX('Job Cost Report'!$F:$F,MATCH($C13,'Job Cost Report'!$B:$B,0)),"") | C13: 9.1.3 | D13: =IFERROR(INDEX('Job Cost Report'!$C:$C,MATCH($C13,'Job Cost Report'!$B:$B,0)),"") | E13: =SUMIF('Job Cost Report'!$B:$B,$C13,'Job Cost Report'!$I:$I) | F13: =SUMIF('Job Cost Report'!$B:$B,$C13,'Job Cost Report'!$J:$J) | G13: =SUMIF('Job Cost Report'!$B:$B,$C13,'Job Cost Report'!$K:$K) | H13: =SUMIF('Job Cost Report'!$B:$B,$C13,'Job Cost Report'!$L:$L)
A14: =IFERROR(INDEX('Job Cost Report'!$E:$E,MATCH($C14,'Job Cost Report'!$B:$B,0)),"") | B14: =IFERROR(INDEX('Job Cost Report'!$F:$F,MATCH($C14,'Job Cost Report'!$B:$B,0)),"") | C14: 9.2.1 | D14: =IFERROR(INDEX('Job Cost Report'!$C:$C,MATCH($C14,'Job Cost Report'!$B:$B,0)),"") | E14: =SUMIF('Job Cost Report'!$B:$B,$C14,'Job Cost Report'!$I:$I) | F14: =SUMIF('Job Cost Report'!$B:$B,$C14,'Job Cost Report'!$J:$J) | G14: =SUMIF('Job Cost Report'!$B:$B,$C14,'Job Cost Report'!$K:$K) | H14: =SUMIF('Job Cost Report'!$B:$B,$C14,'Job Cost Report'!$L:$L)
A15: =IFERROR(INDEX('Job Cost Report'!$E:$E,MATCH($C15,'Job Cost Report'!$B:$B,0)),"") | B15: =IFERROR(INDEX('Job Cost Report'!$F:$F,MATCH($C15,'Job Cost Report'!$B:$B,0)),"") | C15: 9.3.1 | D15: =IFERROR(INDEX('Job Cost Report'!$C:$C,MATCH($C15,'Job Cost Report'!$B:$B,0)),"") | E15: =SUMIF('Job Cost Report'!$B:$B,$C15,'Job Cost Report'!$I:$I) | F15: =SUMIF('Job Cost Report'!$B:$B,$C15,'Job Cost Report'!$J:$J) | G15: =SUMIF('Job Cost Report'!$B:$B,$C15,'Job Cost Report'!$K:$K) | H15: =SUMIF('Job Cost Report'!$B:$B,$C15,'Job Cost Report'!$L:$L)
... A80: =IFERROR(INDEX('Job Cost Report'!$E:$E,MATCH($C80,'Job Cost Report'!$B:$B,0)),"") | B80: =IFERROR(INDEX('Job Cost Report'!$F:$F,MATCH($C80,'Job Cost Report'!$B:$B,0)),"") | C80: 7.1 | D80: =IFERROR(INDEX('Job Cost Report'!$C:$C,MATCH($C80,'Job Cost Report'!$B:$B,0)),"") | E80: =SUMIF('Job Cost Report'!$B:$B,$C80,'Job Cost Report'!$I:$I) | F80: =SUMIF('Job Cost Report'!$B:$B,$C80,'Job Cost Report'!$J:$J) | G80: =SUMIF('Job Cost Report'!$B:$B,$C80,'Job Cost Report'!$K:$K) | H80: =SUMIF('Job Cost Report'!$B:$B,$C80,'Job Cost Report'!$L:$L)

Sheet Job Cost Report
A1: DASHBOARD VENTANAS — Job Cost Report
A2: Modelo vivo. Editá el LEDGER y todo recalcula.
N3: Q1 2026 | O3: Q1 2026 | P3: Q1 2026 | Q3: Q1 2026 | R3: Q1 2026 | S3: Q1 2026 | T3: Q1 2026 | U3: Q1 2026 | V3: Q1 2026 | W3: Q1 2026 | X3: Q1 2026 | Y3: Q1 2026 | Z3: Q1 2026 | AA3: Q1 2026 | AB3: Q1 2026 | AC3: Q1 2026 | AD3: Q1 2026 | AE3: Q2 2026 | AF3: Q2 2026 | AG3: Q2 2026 | AH3: Q2 2026 | AI3: Q2 2026 | AJ3: Q2 2026 | AK3: Q2 2026 | AL3: Q2 2026 | AM3: Q2 2026 | AN3: Q2 2026 | AO3: Q2 2026 | AP3: Q2 2026 | AQ3: Q2 2026 | AR3: Q2 2026 | AS3: Q2 2026 | AT3: Q2 2026 | AU3: Q2 2026 | AV3: Q3 2026 | AW3: Q3 2026 | AX3: Q3 2026 | AY3: Q3 2026 | AZ3: Q3 2026 | BA3: Q3 2026 | BB3: Q3 2026 | BC3: Q3 2026 | BD3: Q3 2026 | BE3: Q3 2026 | BF3: Q3 2026 | BG3: Q3 2026 | BH3: Q3 2026 | BI3: Q3 2026 | BJ3: Q3 2026 | BK3: Q3 2026 | BL3: Q3 2026 | BM3: Q4 2026 | BN3: Q4 2026 | BO3: Q4 2026 | BP3: Q4 2026 | BQ3: Q4 2026 | BR3: Q4 2026 | BS3: Q4 2026 | BT3: Q4 2026 | BU3: Q4 2026 | BV3: Q4 2026 | BW3: Q4 2026 | BX3: Q4 2026 | BY3: Q4 2026 | BZ3: Q4 2026 | CA3: Q4 2026 | CB3: Q4 2026 | CC3: Q4 2026
N4: JAN 2026 | O4: JAN 2026 | P4: JAN 2026 | Q4: JAN 2026 | R4: MES | S4: FEB 2026 | T4: FEB 2026 | U4: FEB 2026 | V4: FEB 2026 | W4: MES | X4: MAR 2026 | Y4: MAR 2026 | Z4: MAR 2026 | AA4: MAR 2026 | AB4: MAR 2026 | AC4: MES | AD4: TRIMESTRE | AE4: APR 2026 | AF4: APR 2026 | AG4: APR 2026 | AH4: APR 2026 | AI4: MES | AJ4: MAY 2026 | AK4: MAY 2026 | AL4: MAY 2026 | AM4: MAY 2026 | AN4: MES | AO4: JUN 2026 | AP4: JUN 2026 | AQ4: JUN 2026 | AR4: JUN 2026 | AS4: JUN 2026 | AT4: MES | AU4: TRIMESTRE | AV4: JUL 2026 | AW4: JUL 2026 | AX4: JUL 2026 | AY4: JUL 2026 | AZ4: MES | BA4: AUG 2026 | BB4: AUG 2026 | BC4: AUG 2026 | BD4: AUG 2026 | BE4: AUG 2026 | BF4: MES | BG4: SEP 2026 | BH4: SEP 2026 | BI4: SEP 2026 | BJ4: SEP 2026 | BK4: MES | BL4: TRIMESTRE | BM4: OCT 2026 | BN4: OCT 2026 | BO4: OCT 2026 | BP4: OCT 2026 | BQ4: MES | BR4: NOV 2026 | BS4: NOV 2026 | BT4: NOV 2026 | BU4: NOV 2026 | BV4: NOV 2026 | BW4: MES | BX4: DEC 2026 | BY4: DEC 2026 | BZ4: DEC 2026 | CA4: DEC 2026 | CB4: MES | CC4: TRIMESTRE
A5: Status | B5: WBS | C5: Task Title | D5: Owner | E5: Category | F5: Phase | G5: Budget Original | H5: Budget Change | I5: Budget Revised | J5: Spend | K5: Remaining | L5: Forecast | M5: Variance | N5: 5 | O5: 12 | P5: 19 | Q5: 26 | R5: JAN | S5: 2 | T5: 9 | U5: 16 | V5: 23 | W5: FEB | X5: 2 | Y5: 9 | Z5: 16 | AA5: 23 | AB5: 30 | AC5: MAR | AD5: Q1 2026 | AE5: 6 | AF5: 13 | AG5: 20 | AH5: 27 | AI5: APR | AJ5: 4 | AK5: 11 | AL5: 18 | AM5: 25 | AN5: MAY | AO5: 1 | AP5: 8 | AQ5: 15 | AR5: 22 | AS5: 29 | AT5: JUN | AU5: Q2 2026 | AV5: 6 | AW5: 13 | AX5: 20 | AY5: 27 | AZ5: JUL | BA5: 3 | BB5: 10 | BC5: 17 | BD5: 24 | BE5: 31 | BF5: AUG | BG5: 7 | BH5: 14 | BI5: 21 | BJ5: 28 | BK5: SEP | BL5: Q3 2026 | BM5: 5 | BN5: 12 | BO5: 19 | BP5: 26 | BQ5: OCT | BR5: 2 | BS5: 9 | BT5: 16 | BU5: 23 | BV5: 30 | BW5: NOV | BX5: 7 | BY5: 14 | BZ5: 21 | CA5: 28 | CB5: DEC | CC5: Q4 2026 | CD5: TOTAL
C6: TOTAL <object object at 0x7f16e877ac70>
A7: 0-PROPERTY ACQUISITION
A8: Completed | B8: 0.0001 | C8: Due Diligence / Closing Costs | D8: HOVDE | E8: 0-Property Acquisition | F8: Phase 1 | G8: 388000 | H8: 415720.07 | I8: =G8+H8 | J8: =SUMIF(LEDGER!$A:$A,$B8,LEDGER!$G:$G) | K8: =I8-J8 | L8: =J8+CD8 | M8: =I8-L8 | R8: =SUM(N8:Q8) | W8: =SUM(S8:V8) | AC8: =SUM(X8:AB8) | AD8: =R8+W8+AC8 | AI8: =SUM(AE8:AH8) | AN8: =SUM(AJ8:AM8) | AT8: =SUM(AO8:AS8) | AU8: =AI8+AN8+AT8 | AZ8: =SUM(AV8:AY8) | BF8: =SUM(BA8:BE8) | BK8: =SUM(BG8:BJ8) | BL8: =AZ8+BF8+BK8 | BQ8: =SUM(BM8:BP8) | BW8: =SUM(BR8:BV8) | CB8: =SUM(BX8:CA8) | CC8: =BQ8+BW8+CB8 | CD8: =AD8+AU8+BL8+CC8
A9: In process | B9: 0.0002 | C9: Property Acquisition | D9: Partnership | E9: 0-Property Acquisition | F9: Phase 1 | G9: 11250000 | H9: 0 | I9: =G9+H9 | J9: =SUMIF(LEDGER!$A:$A,$B9,LEDGER!$G:$G) | K9: =I9-J9 | L9: =J9+CD9 | M9: =I9-L9 | R9: =SUM(N9:Q9) | W9: =SUM(S9:V9) | AC9: =SUM(X9:AB9) | AD9: =R9+W9+AC9 | AI9: =SUM(AE9:AH9) | AN9: =SUM(AJ9:AM9) | AT9: =SUM(AO9:AS9) | AU9: =AI9+AN9+AT9 | AZ9: =SUM(AV9:AY9) | BF9: =SUM(BA9:BE9) | BJ9: 1875000 | BK9: =SUM(BG9:BJ9) | BL9: =AZ9+BF9+BK9 | BQ9: =SUM(BM9:BP9) | BW9: =SUM(BR9:BV9) | CB9: =SUM(BX9:CA9) | CC9: =BQ9+BW9+CB9 | CD9: =AD9+AU9+BL9+CC9
C10: TOTAL 0-Property Acquisition | G10: =G8+G9 | H10: =H8+H9 | I10: =I8+I9 | J10: =J8+J9 | K10: =K8+K9 | L10: =L8+L9 | M10: =M8+M9 | R10: =R8+R9 | W10: =W8+W9 | AC10: =AC8+AC9 | AD10: =AD8+AD9 | AI10: =AI8+AI9 | AN10: =AN8+AN9 | AT10: =AT8+AT9 | AU10: =AU8+AU9 | AZ10: =AZ8+AZ9 | BF10: =BF8+BF9 | BK10: =BK8+BK9 | BL10: =BL8+BL9 | BQ10: =BQ8+BQ9 | BW10: =BW8+BW9 | CB10: =CB8+CB9 | CC10: =CC8+CC9 | CD10: =CD8+CD9
A11: CFIA CONDO
A12: In process | B12: 2.1.1 | C12: Pre Workshop | D12: EDSA | E12: CFIA Condo | F12: DESIGN | G12: 14500 | H12: 0 | I12: =G12+H12 | J12: =SUMIF(LEDGER!$A:$A,$B12,LEDGER!$G:$G) | K12: =I12-J12 | L12: =J12+CD12 | M12: =I12-L12 | R12: =SUM(N12:Q12) | W12: =SUM(S12:V12) | AC12: =SUM(X12:AB12) | AD12: =R12+W12+AC12 | AE12: 14500 | AI12: =SUM(AE12:AH12) | AN12: =SUM(AJ12:AM12) | AT12: =SUM(AO12:AS12) | AU12: =AI12+AN12+AT12 | AZ12: =SUM(AV12:AY12) | BF12: =SUM(BA12:BE12) | BK12: =SUM(BG12:BJ12) | BL12: =AZ12+BF12+BK12 | BQ12: =SUM(BM12:BP12) | BW12: =SUM(BR12:BV12) | CB12: =SUM(BX12:CA12) | CC12: =BQ12+BW12+CB12 | CD12: =AD12+AU12+BL12+CC12
A13: Approved | B13: 2.1.2 | C13: Workshop | D13: EDSA | E13: CFIA Condo | F13: DESIGN | G13: 24500 | H13: 29631.6 | I13: =G13+H13 | J13: =SUMIF(LEDGER!$A:$A,$B13,LEDGER!$G:$G) | K13: =I13-J13 | L13: =J13+CD13 | M13: =I13-L13 | R13: =SUM(N13:Q13) | W13: =SUM(S13:V13) | AC13: =SUM(X13:AB13) | AD13: =R13+W13+AC13 | AI13: =SUM(AE13:AH13) | AN13: =SUM(AJ13:AM13) | AT13: =SUM(AO13:AS13) | AU13: =AI13+AN13+AT13 | AZ13: =SUM(AV13:AY13) | BF13: =SUM(BA13:BE13) | BK13: =SUM(BG13:BJ13) | BL13: =AZ13+BF13+BK13 | BQ13: =SUM(BM13:BP13) | BW13: =SUM(BR13:BV13) | CB13: =SUM(BX13:CA13) | CC13: =BQ13+BW13+CB13 | CD13: =AD13+AU13+BL13+CC13
A14: Approved | B14: 2.1.3 | C14: Post Workshop / Conceptual Enlargements | D14: EDSA | E14: CFIA Condo | F14: DESIGN | G14: 48500 | H14: 0 | I14: =G14+H14 | J14: =SUMIF(LEDGER!$A:$A,$B14,LEDGER!$G:$G) | K14: =I14-J14 | L14: =J14+CD14 | M14: =I14-L14 | R14: =SUM(N14:Q14) | W14: =SUM(S14:V14) | AC14: =SUM(X14:AB14) | AD14: =R14+W14+AC14 | AI14: =SUM(AE14:AH14) | AN14: =SUM(AJ14:AM14) | AO14: 41000 | AT14: =SUM(AO14:AS14) | AU14: =AI14+AN14+AT14 | AZ14: =SUM(AV14:AY14) | BF14: =SUM(BA14:BE14) | BK14: =SUM(BG14:BJ14) | BL14: =AZ14+BF14+BK14 | BQ14: =SUM(BM14:BP14) | BW14: =SUM(BR14:BV14) | CB14: =SUM(BX14:CA14) | CC14: =BQ14+BW14+CB14 | CD14: =AD14+AU14+BL14+CC14
A15: Approved | B15: 2.1.4 | C15: Travel Expenses MP | D15: EDSA | E15: CFIA Condo | F15: DESIGN | G15: 5000 | H15: 0 | I15: =G15+H15 | J15: =SUMIF(LEDGER!$A:$A,$B15,LEDGER!$G:$G) | K15: =I15-J15 | L15: =J15+CD15 | M15: =I15-L15 | R15: =SUM(N15:Q15) | W15: =SUM(S15:V15) | AC15: =SUM(X15:AB15) | AD15: =R15+W15+AC15 | AI15: =SUM(AE15:AH15) | AN15: =SUM(AJ15:AM15) | AT15: =SUM(AO15:AS15) | AU15: =AI15+AN15+AT15 | AZ15: =SUM(AV15:AY15) | BA15: 5000 | BF15: =SUM(BA15:BE15) | BK15: =SUM(BG15:BJ15) | BL15: =AZ15+BF15+BK15 | BQ15: =SUM(BM15:BP15) | BW15: =SUM(BR15:BV15) | CB15: =SUM(BX15:CA15) | CC15: =BQ15+BW15+CB15 | CD15: =AD15+AU15+BL15+CC15
A16: Approved | B16: 2.2 | C16: Schematic Design | D16: EDSA | E16: CFIA Condo | F16: DESIGN | G16: 100000 | H16: 0 | I16: =G16+H16 | J16: =SUMIF(LEDGER!$A:$A,$B16,LEDGER!$G:$G) | K16: =I16-J16 | L16: =J16+CD16 | M16: =I16-L16 | R16: =SUM(N16:Q16) | W16: =SUM(S16:V16) | AC16: =SUM(X16:AB16) | AD16: =R16+W16+AC16 | AI16: =SUM(AE16:AH16) | AN16: =SUM(AJ16:AM16) | AT16: =SUM(AO16:AS16) | AU16: =AI16+AN16+AT16 | AZ16: =SUM(AV16:AY16) | BF16: =SUM(BA16:BE16) | BG16: 25000 | BH16: 25000 | BI16: 25000 | BJ16: 25000 | BK16: =SUM(BG16:BJ16) | BL16: =AZ16+BF16+BK16 | BQ16: =SUM(BM16:BP16) | BW16: =SUM(BR16:BV16) | CB16: =SUM(BX16:CA16) | CC16: =BQ16+BW16+CB16 | CD16: =AD16+AU16+BL16+CC16
C17: TOTAL CFIA Condo | G17: =G12+G13+G14+G15+G16 | H17: =H12+H13+H14+H15+H16 | I17: =I12+I13+I14+I15+I16 | J17: =J12+J13+J14+J15+J16 | K17: =K12+K13+K14+K15+K16 | L17: =L12+L13+L14+L15+L16 | M17: =M12+M13+M14+M15+M16 | R17: =R12+R13+R14+R15+R16 | W17: =W12+W13+W14+W15+W16 | AC17: =AC12+AC13+AC14+AC15+AC16 | AD17: =AD12+AD13+AD14+AD15+AD16 | AI17: =AI12+AI13+AI14+AI15+AI16 | AN17: =AN12+AN13+AN14+AN15+AN16 | AT17: =AT12+AT13+AT14+AT15+AT16 | AU17: =AU12+AU13+AU14+AU15+AU16 | AZ17: =AZ12+AZ13+AZ14+AZ15+AZ16 | BF17: =BF12+BF13+BF14+BF15+BF16 | BK17: =BK12+BK13+BK14+BK15+BK16 | BL17: =BL12+BL13+BL14+BL15+BL16 | BQ17: =BQ12+BQ13+BQ14+BQ15+BQ16 | BW17: =BW12+BW13+BW14+BW15+BW16 | CB17: =CB12+CB13+CB14+CB15+CB16 | CC17: =CC12+CC13+CC14+CC15+CC16 | CD17: =CD12+CD13+CD14+CD15+CD16
A18: CFIA INFRASTRUCTURE
A19: In process | B19: 9.1.1 | C19: Phase 1/2/3 Pre Consultations | D19: DEHC | E19: CFIA Infrastructure | F19: Phase 1 | G19: 0 | H19: 5424 | I19: =G19+H19 | J19: =SUMIF(LEDGER!$A:$A,$B19,LEDGER!$G:$G) | K19: =I19-J19 | L19: =J19+CD19 | M19: =I19-L19 | R19: =SUM(N19:Q19) | S19: -1921 | W19: =SUM(S19:V19) | AC19: =SUM(X19:AB19) | AD19: =R19+W19+AC19 | AI19: =SUM(AE19:AH19) | AN19: =SUM(AJ19:AM19) | AT19: =SUM(AO19:AS19) | AU19: =AI19+AN19+AT19 | AZ19: =SUM(AV19:AY19) | BF19: =SUM(BA19:BE19) | BK19: =SUM(BG19:BJ19) | BL19: =AZ19+BF19+BK19 | BQ19: =SUM(BM19:BP19) | BW19: =SUM(BR19:BV19) | CB19: =SUM(BX19:CA19) | CC19: =BQ19+BW19+CB19 | CD19: =AD19+AU19+BL19+CC19
A20: In process | B20: 9.1.2 | C20: Phase 1/2/3 Discharge permit MOPT and Municipality | D20: DEHC | E20: CFIA Infrastructure | F20: Phase 2 | G20: 0 | H20: 1356 | I20: =G20+H20 | J20: =SUMIF(LEDGER!$A:$A,$B20,LEDGER!$G:$G) | K20: =I20-J20 | L20: =J20+CD20 | M20: =I20-L20 | R20: =SUM(N20:Q20) | S20: -678 | W20: =SUM(S20:V20) | AC20: =SUM(X20:AB20) | AD20: =R20+W20+AC20 | AI20: =SUM(AE20:AH20) | AN20: =SUM(AJ20:AM20) | AT20: =SUM(AO20:AS20) | AU20: =AI20+AN20+AT20 | AZ20: =SUM(AV20:AY20) | BF20: =SUM(BA20:BE20) | BK20: =SUM(BG20:BJ20) | BL20: =AZ20+BF20+BK20 | BQ20: =SUM(BM20:BP20) | BW20: =SUM(BR20:BV20) | CB20: =SUM(BX20:CA20) | CC20: =BQ20+BW20+CB20 | CD20: =AD20+AU20+BL20+CC20
A21: Approved | B21: 9.1.3 | C21: Phase 1 Permit (Includes topo of the existing road) | D21: DEHC | E21: CFIA Infrastructure | F21: Phase 1 | G21: 0 | H21: 16385 | I21: =G21+H21 | J21: =SUMIF(LEDGER!$A:$A,$B21,LEDGER!$G:$G) | K21: =I21-J21 | L21: =J21+CD21 | M21: =I21-L21 | R21: =SUM(N21:Q21) | W21: =SUM(S21:V21) | AC21: =SUM(X21:AB21) | AD21: =R21+W21+AC21 | AI21: =SUM(AE21:AH21) | AN21: =SUM(AJ21:AM21) | AT21: =SUM(AO21:AS21) | AU21: =AI21+AN21+AT21 | AZ21: =SUM(AV21:AY21) | BF21: =SUM(BA21:BE21) | BK21: =SUM(BG21:BJ21) | BL21: =AZ21+BF21+BK21 | BQ21: =SUM(BM21:BP21) | BW21: =SUM(BR21:BV21) | CB21: =SUM(BX21:CA21) | CC21: =BQ21+BW21+CB21 | CD21: =AD21+AU21+BL21+CC21
A22: Approved | B22: 9.2.1 | C22: Phase 2 Permit | D22: DEHC | E22: CFIA Infrastructure | F22: Phase 2 | G22: 0 | H22: 8814 | I22: =G22+H22 | J22: =SUMIF(LEDGER!$A:$A,$B22,LEDGER!$G:$G) | K22: =I22-J22 | L22: =J22+CD22 | M22: =I22-L22 | R22: =SUM(N22:Q22) | W22: =SUM(S22:V22) | AA22: 8814 | AC22: =SUM(X22:AB22) | AD22: =R22+W22+AC22 | AI22: =SUM(AE22:AH22) | AN22: =SUM(AJ22:AM22) | AT22: =SUM(AO22:AS22) | AU22: =AI22+AN22+AT22 | AZ22: =SUM(AV22:AY22) | BF22: =SUM(BA22:BE22) | BK22: =SUM(BG22:BJ22) | BL22: =AZ22+BF22+BK22 | BQ22: =SUM(BM22:BP22) | BW22: =SUM(BR22:BV22) | CB22: =SUM(BX22:CA22) | CC22: =BQ22+BW22+CB22 | CD22: =AD22+AU22+BL22+CC22
A23: Approved | B23: 9.3.1 | C23: Phase 3 Permit | D23: DEHC | E23: CFIA Infrastructure | F23: Phase 3 | G23: 0 | H23: 1356 | I23: =G23+H23 | J23: =SUMIF(LEDGER!$A:$A,$B23,LEDGER!$G:$G) | K23: =I23-J23 | L23: =J23+CD23 | M23: =I23-L23 | R23: =SUM(N23:Q23) | W23: =SUM(S23:V23) | AA23: 1356 | AC23: =SUM(X23:AB23) | AD23: =R23+W23+AC23 | AI23: =SUM(AE23:AH23) | AN23: =SUM(AJ23:AM23) | AT23: =SUM(AO23:AS23) | AU23: =AI23+AN23+AT23 | AZ23: =SUM(AV23:AY23) | BF23: =SUM(BA23:BE23) | BK23: =SUM(BG23:BJ23) | BL23: =AZ23+BF23+BK23 | BQ23: =SUM(BM23:BP23) | BW23: =SUM(BR23:BV23) | CB23: =SUM(BX23:CA23) | CC23: =BQ23+BW23+CB23 | CD23: =AD23+AU23+BL23+CC23
A24: Approved | B24: 7.2 | C24: Plan and approval of the two condominiums | D24: Blake | E24: CFIA Infrastructure | F24: Phase 3 | G24: 0 | H24: 0 | I24: =G24+H24 | J24: =SUMIF(LEDGER!$A:$A,$B24,LEDGER!$G:$G) | K24: =I24-J24 | L24: =J24+CD24 | M24: =I24-L24 | R24: =SUM(N24:Q24) | W24: =SUM(S24:V24) | AC24: =SUM(X24:AB24) | AD24: =R24+W24+AC24 | AI24: =SUM(AE24:AH24) | AN24: =SUM(AJ24:AM24) | AT24: =SUM(AO24:AS24) | AU24: =AI24+AN24+AT24 | AZ24: =SUM(AV24:AY24) | BF24: =SUM(BA24:BE24) | BK24: =SUM(BG24:BJ24) | BL24: =AZ24+BF24+BK24 | BQ24: =SUM(BM24:BP24) | BW24: =SUM(BR24:BV24) | CB24: =SUM(BX24:CA24) | CC24: =BQ24+BW24+CB24 | CD24: =AD24+AU24+BL24+CC24
A25: Approved | B25: 7.3 | C25: Cadastre Plan (only when we want to convey) | D25: Surveyor | E25: CFIA Infrastructure | F25: Phase 3 | G25: 102162.45 | H25: 0 | I25: =G25+H25 | J25: =SUMIF(LEDGER!$A:$A,$B25,LEDGER!$G:$G) | K25: =I25-J25 | L25: =J25+CD25 | M25: =I25-L25 | R25: =SUM(N25:Q25) | W25: =SUM(S25:V25) | AC25: =SUM(X25:AB25) | AD25: =R25+W25+AC25 | AI25: =SUM(AE25:AH25) | AJ25: 51081.22 | AN25: =SUM(AJ25:AM25) | AT25: =SUM(AO25:AS25) | AU25: =AI25+AN25+AT25 | AZ25: =SUM(AV25:AY25) | BF25: =SUM(BA25:BE25) | BG25: 51081.22 | BK25: =SUM(BG25:BJ25) | BL25: =AZ25+BF25+BK25 | BQ25: =SUM(BM25:BP25) | BW25: =SUM(BR25:BV25) | CB25: =SUM(BX25:CA25) | CC25: =BQ25+BW25+CB25 | CD25: =AD25+AU25+BL25+CC25
A26: Approved | B26: 7.4 | C26: CFIA (1%) - Whole Project | D26: Blake | E26: CFIA Infrastructure | F26: Phase 3 | G26: 265000 | H26: 0 | I26: =G26+H26 | J26: =SUMIF(LEDGER!$A:$A,$B26,LEDGER!$G:$G) | K26: =I26-J26 | L26: =J26+CD26 | M26: =I26-L26 | R26: =SUM(N26:Q26) | W26: =SUM(S26:V26) | AC26: =SUM(X26:AB26) | AD26: =R26+W26+AC26 | AI26: =SUM(AE26:AH26) | AN26: =SUM(AJ26:AM26) | AT26: =SUM(AO26:AS26) | AU26: =AI26+AN26+AT26 | AZ26: =SUM(AV26:AY26) | BA26: 265000 | BF26: =SUM(BA26:BE26) | BK26: =SUM(BG26:BJ26) | BL26: =AZ26+BF26+BK26 | BQ26: =SUM(BM26:BP26) | BW26: =SUM(BR26:BV26) | CB26: =SUM(BX26:CA26) | CC26: =BQ26+BW26+CB26 | CD26: =AD26+AU26+BL26+CC26
A27: Approved | B27: 7.5 | C27: INS (1.298%) - Phase Only | D27: Blake | E27: CFIA Infrastructure | F27: Phase 3 | G27: 129800 | H27: 0 | I27: =G27+H27 | J27: =SUMIF(LEDGER!$A:$A,$B27,LEDGER!$G:$G) | K27: =I27-J27 | L27: =J27+CD27 | M27: =I27-L27 | R27: =SUM(N27:Q27) | W27: =SUM(S27:V27) | AC27: =SUM(X27:AB27) | AD27: =R27+W27+AC27 | AI27: =SUM(AE27:AH27) | AN27: =SUM(AJ27:AM27) | AT27: =SUM(AO27:AS27) | AU27: =AI27+AN27+AT27 | AZ27: =SUM(AV27:AY27) | BF27: =SUM(BA27:BE27) | BK27: =SUM(BG27:BJ27) | BL27: =AZ27+BF27+BK27 | BQ27: =SUM(BM27:BP27) | BU27: 129800 | BW27: =SUM(BR27:BV27) | CB27: =SUM(BX27:CA27) | CC27: =BQ27+BW27+CB27 | CD27: =AD27+AU27+BL27+CC27
A28: Approved | B28: 7.6 | C28: SETENA Bond (1.5% Value) - Phase Only | D28: Partnership | E28: CFIA Infrastructure | F28: Phase 3 | G28: 300000 | H28: 0 | I28: =G28+H28 | J28: =SUMIF(LEDGER!$A:$A,$B28,LEDGER!$G:$G) | K28: =I28-J28 | L28: =J28+CD28 | M28: =I28-L28 | R28: =SUM(N28:Q28) | W28: =SUM(S28:V28) | AC28: =SUM(X28:AB28) | AD28: =R28+W28+AC28 | AI28: =SUM(AE28:AH28) | AN28: =SUM(AJ28:AM28) | AT28: =SUM(AO28:AS28) | AU28: =AI28+AN28+AT28 | AZ28: =SUM(AV28:AY28) | BF28: =SUM(BA28:BE28) | BK28: =SUM(BG28:BJ28) | BL28: =AZ28+BF28+BK28 | BQ28: =SUM(BM28:BP28) | BR28: 300000 | BW28: =SUM(BR28:BV28) | CB28: =SUM(BX28:CA28) | CC28: =BQ28+BW28+CB28 | CD28: =AD28+AU28+BL28+CC28
A29: Approved | B29: 7.7 | C29: Municipality (1%) - Phase Only | D29: Permit Engineer | E29: CFIA Infrastructure | F29: Phase 3 | G29: 100000 | H29: 0 | I29: =G29+H29 | J29: =SUMIF(LEDGER!$A:$A,$B29,LEDGER!$G:$G) | K29: =I29-J29 | L29: =J29+CD29 | M29: =I29-L29 | R29: =SUM(N29:Q29) | W29: =SUM(S29:V29) | AC29: =SUM(X29:AB29) | AD29: =R29+W29+AC29 | AI29: =SUM(AE29:AH29) | AN29: =SUM(AJ29:AM29) | AT29: =SUM(AO29:AS29) | AU29: =AI29+AN29+AT29 | AZ29: =SUM(AV29:AY29) | BF29: =SUM(BA29:BE29) | BK29: =SUM(BG29:BJ29) | BL29: =AZ29+BF29+BK29 | BQ29: =SUM(BM29:BP29) | BW29: =SUM(BR29:BV29) | BX29: 100000 | CB29: =SUM(BX29:CA29) | CC29: =BQ29+BW29+CB29 | CD29: =AD29+AU29+BL29+CC29
C30: TOTAL CFIA Infrastructure | G30: =G19+G20+G21+G22+G23+G24+G25+G26+G27+G28+G29 | H30: =H19+H20+H21+H22+H23+H24+H25+H26+H27+H28+H29 | I30: =I19+I20+I21+I22+I23+I24+I25+I26+I27+I28+I29 | J30: =J19+J20+J21+J22+J23+J24+J25+J26+J27+J28+J29 | K30: =K19+K20+K21+K22+K23+K24+K25+K26+K27+K28+K29 | L30: =L19+L20+L21+L22+L23+L24+L25+L26+L27+L28+L29 | M30: =M19+M20+M21+M22+M23+M24+M25+M26+M27+M28+M29 | R30: =R19+R20+R21+R22+R23+R24+R25+R26+R27+R28+R29 | W30: =W19+W20+W21+W22+W23+W24+W25+W26+W27+W28+W29 | AC30: =AC19+AC20+AC21+AC22+AC23+AC24+AC25+AC26+AC27+AC28+AC29 | AD30: =AD19+AD20+AD21+AD22+AD23+AD24+AD25+AD26+AD27+AD28+AD29 | AI30: =AI19+AI20+AI21+AI22+AI23+AI24+AI25+AI26+AI27+AI28+AI29 | AN30: =AN19+AN20+AN21+AN22+AN23+AN24+AN25+AN26+AN27+AN28+AN29 | AT30: =AT19+AT20+AT21+AT22+AT23+AT24+AT25+AT26+AT27+AT28+AT29 | AU30: =AU19+AU20+AU21+AU22+AU23+AU24+AU25+AU26+AU27+AU28+AU29 | AZ30: =AZ19+AZ20+AZ21+AZ22+AZ23+AZ24+AZ25+AZ26+AZ27+AZ28+AZ29 | BF30: =BF19+BF20+BF21+BF22+BF23+BF24+BF25+BF26+BF27+BF28+BF29 | BK30: =BK19+BK20+BK21+BK22+BK23+BK24+BK25+BK26+BK27+BK28+BK29 | BL30: =BL19+BL20+BL21+BL22+BL23+BL24+BL25+BL26+BL27+BL28+BL29 | BQ30: =BQ19+BQ20+BQ21+BQ22+BQ23+BQ24+BQ25+BQ26+BQ27+BQ28+BQ29 | BW30: =BW19+BW20+BW21+BW22+BW23+BW24+BW25+BW26+BW27+BW28+BW29 | CB30: =CB19+CB20+CB21+CB22+CB23+CB24+CB25+CB26+CB27+CB28+CB29 | CC30: =CC19+CC20+CC21+CC22+CC23+CC24+CC25+CC26+CC27+CC28+CC29 | CD30: =CD19+CD20+CD21+CD22+CD23+CD24+CD25+CD26+CD27+CD28+CD29
A31: CONCESSIONS
A32: In process | B32: 5.1 | C32: Preliminar Study for PNE applications in ACOSA, SINAC, and Muni | D32: Eduardo | E32: Concessions | F32: SETENA Regional Review | G32: 0 | H32: 5000 | I32: =G32+H32 | J32: =SUMIF(LEDGER!$A:$A,$B32,LEDGER!$G:$G) | K32: =I32-J32 | L32: =J32+CD32 | M32: =I32-L32 | R32: =SUM(N32:Q32) | W32: =SUM(S32:V32) | AC32: =SUM(X32:AB32) | AD32: =R32+W32+AC32 | AI32: =SUM(AE32:AH32) | AN32: =SUM(AJ32:AM32) | AT32: =SUM(AO32:AS32) | AU32: =AI32+AN32+AT32 | AZ32: =SUM(AV32:AY32) | BF32: =SUM(BA32:BE32) | BK32: =SUM(BG32:BJ32) | BL32: =AZ32+BF32+BK32 | BM32: 5000 | BQ32: =SUM(BM32:BP32) | BW32: =SUM(BR32:BV32) | CB32: =SUM(BX32:CA32) | CC32: =BQ32+BW32+CB32 | CD32: =AD32+AU32+BL32+CC32
A33: In process | B33: 5.2 | C33: Engineering diagnosis to apply reversion of Patrimony areas to Muni ( to apply later for concessions ) | D33: Eduardo consultant | E33: Concessions | F33: SETENA Regional Review | G33: 9944 | H33: 0 | I33: =G33+H33 | J33: =SUMIF(LEDGER!$A:$A,$B33,LEDGER!$G:$G) | K33: =I33-J33 | L33: =J33+CD33 | M33: =I33-L33 | R33: =SUM(N33:Q33) | W33: =SUM(S33:V33) | AA33: 4972 | AC33: =SUM(X33:AB33) | AD33: =R33+W33+AC33 | AI33: =SUM(AE33:AH33) | AN33: =SUM(AJ33:AM33) | AT33: =SUM(AO33:AS33) | AU33: =AI33+AN33+AT33 | AZ33: =SUM(AV33:AY33) | BF33: =SUM(BA33:BE33) | BK33: =SUM(BG33:BJ33) | BL33: =AZ33+BF33+BK33 | BM33: 4972 | BQ33: =SUM(BM33:BP33) | BW33: =SUM(BR33:BV33) | CB33: =SUM(BX33:CA33) | CC33: =BQ33+BW33+CB33 | CD33: =AD33+AU33+BL33+CC33
A34: Approved | B34: 5.3 | C34: Application/ project description for PNE MINAET | D34: Eduardo | E34: Concessions | F34: SETENA Regional Review | G34: 15876.5 | H34: 0 | I34: =G34+H34 | J34: =SUMIF(LEDGER!$A:$A,$B34,LEDGER!$G:$G) | K34: =I34-J34 | L34: =J34+CD34 | M34: =I34-L34 | R34: =SUM(N34:Q34) | W34: =SUM(S34:V34) | AC34: =SUM(X34:AB34) | AD34: =R34+W34+AC34 | AI34: =SUM(AE34:AH34) | AJ34: 15876.5 | AN34: =SUM(AJ34:AM34) | AT34: =SUM(AO34:AS34) | AU34: =AI34+AN34+AT34 | AZ34: =SUM(AV34:AY34) | BF34: =SUM(BA34:BE34) | BK34: =SUM(BG34:BJ34) | BL34: =AZ34+BF34+BK34 | BQ34: =SUM(BM34:BP34) | BW34: =SUM(BR34:BV34) | CB34: =SUM(BX34:CA34) | CC34: =BQ34+BW34+CB34 | CD34: =AD34+AU34+BL34+CC34
A35: Approved | B35: 5.4 | C35: Survey new plans - Adjust to Government Regs | D35: Surveyor | E35: Concessions | F35: SETENA Regional Review | G35: 72207 | H35: 0 | I35: =G35+H35 | J35: =SUMIF(LEDGER!$A:$A,$B35,LEDGER!$G:$G) | K35: =I35-J35 | L35: =J35+CD35 | M35: =I35-L35 | R35: =SUM(N35:Q35) | W35: =SUM(S35:V35) | AC35: =SUM(X35:AB35) | AD35: =R35+W35+AC35 | AH35: 16950 | AI35: =SUM(AE35:AH35) | AN35: =SUM(AJ35:AM35) | AO35: 30000 | AT35: =SUM(AO35:AS35) | AU35: =AI35+AN35+AT35 | AV35: 16950 | AY35: 8307 | AZ35: =SUM(AV35:AY35) | BF35: =SUM(BA35:BE35) | BK35: =SUM(BG35:BJ35) | BL35: =AZ35+BF35+BK35 | BQ35: =SUM(BM35:BP35) | BW35: =SUM(BR35:BV35) | CB35: =SUM(BX35:CA35) | CC35: =BQ35+BW35+CB35 | CD35: =AD35+AU35+BL35+CC35
A36: Approved | B36: 5.5 | C36: Create Draft Plans for Development | D36: Randall | E36: Concessions | F36: SETENA Regional Review | G36: 30000 | H36: 0 | I36: =G36+H36 | J36: =SUMIF(LEDGER!$A:$A,$B36,LEDGER!$G:$G) | K36: =I36-J36 | L36: =J36+CD36 | M36: =I36-L36 | R36: =SUM(N36:Q36) | W36: =SUM(S36:V36) | AC36: =SUM(X36:AB36) | AD36: =R36+W36+AC36 | AI36: =SUM(AE36:AH36) | AN36: =SUM(AJ36:AM36) | AO36: 15000 | AT36: =SUM(AO36:AS36) | AU36: =AI36+AN36+AT36 | AX36: 15000 | AZ36: =SUM(AV36:AY36) | BF36: =SUM(BA36:BE36) | BK36: =SUM(BG36:BJ36) | BL36: =AZ36+BF36+BK36 | BQ36: =SUM(BM36:BP36) | BW36: =SUM(BR36:BV36) | CB36: =SUM(BX36:CA36) | CC36: =BQ36+BW36+CB36 | CD36: =AD36+AU36+BL36+CC36
A37: In process | B37: 5.6 | C37: Legal Expenses - Concession MUNI | D37: Herbet | E37: Concessions | F37: SETENA Regional Review | G37: 100000 | H37: 0 | I37: =G37+H37 | J37: =SUMIF(LEDGER!$A:$A,$B37,LEDGER!$G:$G) | K37: =I37-J37 | L37: =J37+CD37 | M37: =I37-L37 | R37: =SUM(N37:Q37) | W37: =SUM(S37:V37) | AC37: =SUM(X37:AB37) | AD37: =R37+W37+AC37 | AI37: =SUM(AE37:AH37) | AN37: =SUM(AJ37:AM37) | AT37: =SUM(AO37:AS37) | AU37: =AI37+AN37+AT37 | AZ37: =SUM(AV37:AY37) | BF37: =SUM(BA37:BE37) | BK37: =SUM(BG37:BJ37) | BL37: =AZ37+BF37+BK37 | BQ37: =SUM(BM37:BP37) | BR37: 100000 | BW37: =SUM(BR37:BV37) | CB37: =SUM(BX37:CA37) | CC37: =BQ37+BW37+CB37 | CD37: =AD37+AU37+BL37+CC37
A38: Approved | B38: 5.7 | C38: Legal Expenses - Land Use SINAC | D38: Eduardo | E38: Concessions | F38: SETENA Regional Review | G38: 50000 | H38: 0 | I38: =G38+H38 | J38: =SUMIF(LEDGER!$A:$A,$B38,LEDGER!$G:$G) | K38: =I38-J38 | L38: =J38+CD38 | M38: =I38-L38 | R38: =SUM(N38:Q38) | W38: =SUM(S38:V38) | AC38: =SUM(X38:AB38) | AD38: =R38+W38+AC38 | AI38: =SUM(AE38:AH38) | AM38: 20000 | AN38: =SUM(AJ38:AM38) | AT38: =SUM(AO38:AS38) | AU38: =AI38+AN38+AT38 | AY38: 20000 | AZ38: =SUM(AV38:AY38) | BF38: =SUM(BA38:BE38) | BJ38: 10000 | BK38: =SUM(BG38:BJ38) | BL38: =AZ38+BF38+BK38 | BQ38: =SUM(BM38:BP38) | BW38: =SUM(BR38:BV38) | CB38: =SUM(BX38:CA38) | CC38: =BQ38+BW38+CB38 | CD38: =AD38+AU38+BL38+CC38
A39: In process | B39: 5.8 | C39: Legal Expenses - Land Use Concessions (ALTA BATALLA)} | D39: Roberto | E39: Concessions | F39: SETENA Regional Review | G39: 14500 | H39: 0 | I39: =G39+H39 | J39: =SUMIF(LEDGER!$A:$A,$B39,LEDGER!$G:$G) | K39: =I39-J39 | L39: =J39+CD39 | M39: =I39-L39 | R39: =SUM(N39:Q39) | W39: =SUM(S39:V39) | AC39: =SUM(X39:AB39) | AD39: =R39+W39+AC39 | AI39: =SUM(AE39:AH39) | AN39: =SUM(AJ39:AM39) | AO39: 7250 | AT39: =SUM(AO39:AS39) | AU39: =AI39+AN39+AT39 | AZ39: =SUM(AV39:AY39) | BF39: =SUM(BA39:BE39) | BK39: =SUM(BG39:BJ39) | BL39: =AZ39+BF39+BK39 | BM39: 7250 | BQ39: =SUM(BM39:BP39) | BW39: =SUM(BR39:BV39) | CB39: =SUM(BX39:CA39) | CC39: =BQ39+BW39+CB39 | CD39: =AD39+AU39+BL39+CC39
A40: Approved | B40: 8.3 | C40: Finalize Creation of Concessions | D40: Blake | E40: Concessions | G40: 42375 | H40: 0 | I40: =G40+H40 | J40: =SUMIF(LEDGER!$A:$A,$B40,LEDGER!$G:$G) | K40: =I40-J40 | L40: =J40+CD40 | M40: =I40-L40 | R40: =SUM(N40:Q40) | W40: =SUM(S40:V40) | AC40: =SUM(X40:AB40) | AD40: =R40+W40+AC40 | AI40: =SUM(AE40:AH40) | AN40: =SUM(AJ40:AM40) | AT40: =SUM(AO40:AS40) | AU40: =AI40+AN40+AT40 | AZ40: =SUM(AV40:AY40) | BF40: =SUM(BA40:BE40) | BK40: =SUM(BG40:BJ40) | BL40: =AZ40+BF40+BK40 | BQ40: =SUM(BM40:BP40) | BW40: =SUM(BR40:BV40) | CA40: 42375 | CB40: =SUM(BX40:CA40) | CC40: =BQ40+BW40+CB40 | CD40: =AD40+AU40+BL40+CC40
...

Sheet Leyenda
B2: Leyenda de estados
C4: Not Started | D4: not_started
C5: In process | D5: in_process
C6: Approved | D6: approved
C7: Attention | D7: attention
C8: Completed | D8: completed
B11: Cómo colapsar
B13: Los botones 1 · 2 · 3 arriba a la izquierda de la hoja Job Cost Report:
B14: 1 → sólo trimestres
B15: 2 → trimestres + meses
B16: 3 → todo el detalle semanal
B17: También sirven los +/− sobre cada grupo de columnas.
B19: Este archivo es un modelo VIVO: las columnas Spend, Remaining,
B20: Forecast, los subtotales y los totales son fórmulas.
B21: Si editás el LEDGER, todo recalcula solo.
